<?xml version="1.0" encoding="UTF-8"?>
<!-- Generated by org.testng.reporters.JUnitReportReporter -->
<testsuite hostname="tangtao-PC" name="main.testcase.Wallet.Withdraw" tests="18" failures="1" timestamp="1 Jun 2016 06:21:41 GMT" time="12.631" errors="0">
  <testcase name="withdraw" time="0.712" classname="main.testcase.Wallet.Withdraw"/>
  <testcase name="withdraw" time="0.638" classname="main.testcase.Wallet.Withdraw"/>
  <testcase name="withdraw" time="0.715" classname="main.testcase.Wallet.Withdraw"/>
  <testcase name="withdraw" time="0.733" classname="main.testcase.Wallet.Withdraw"/>
  <testcase name="withdraw" time="0.734" classname="main.testcase.Wallet.Withdraw"/>
  <testcase name="withdraw" time="0.724" classname="main.testcase.Wallet.Withdraw"/>
  <testcase name="withdraw" time="0.729" classname="main.testcase.Wallet.Withdraw"/>
  <testcase name="withdraw" time="0.663" classname="main.testcase.Wallet.Withdraw"/>
  <testcase name="withdraw" time="0.715" classname="main.testcase.Wallet.Withdraw"/>
  <testcase name="withdraw" time="0.720" classname="main.testcase.Wallet.Withdraw"/>
  <testcase name="withdraw" time="0.717" classname="main.testcase.Wallet.Withdraw"/>
  <testcase name="withdraw" time="0.600" classname="main.testcase.Wallet.Withdraw"/>
  <testcase name="withdraw" time="0.742" classname="main.testcase.Wallet.Withdraw">
    <failure type="java.lang.AssertionError" message="expected [卡号长度不符合] but found [卡号不能为空]">
      <![CDATA[java.lang.AssertionError: expected [卡号长度不符合] but found [卡号不能为空]
	at org.testng.Assert.fail(Assert.java:94)
	at org.testng.Assert.failNotEquals(Assert.java:513)
	at org.testng.Assert.assertEqualsImpl(Assert.java:135)
	at org.testng.Assert.assertEquals(Assert.java:116)
	at org.testng.Assert.assertEquals(Assert.java:190)
	at org.testng.Assert.assertEquals(Assert.java:200)
	at main.testcase.Wallet.Withdraw.withdraw(Withdraw.java:91)
	at sun.reflect.NativeMethodAccessorImpl.invoke0(Native Method)
	at sun.reflect.NativeMethodAccessorImpl.invoke(Unknown Source)
	at sun.reflect.DelegatingMethodAccessorImpl.invoke(Unknown Source)
	at java.lang.reflect.Method.invoke(Unknown Source)
	at org.testng.internal.MethodInvocationHelper.invokeMethod(MethodInvocationHelper.java:86)
	at org.testng.internal.Invoker.invokeMethod(Invoker.java:643)
	at org.testng.internal.Invoker.invokeTestMethod(Invoker.java:820)
	at org.testng.internal.Invoker.invokeTestMethods(Invoker.java:1128)
	at org.testng.internal.TestMethodWorker.invokeTestMethods(TestMethodWorker.java:129)
	at org.testng.internal.TestMethodWorker.run(TestMethodWorker.java:112)
	at org.testng.TestRunner.privateRun(TestRunner.java:782)
	at org.testng.TestRunner.run(TestRunner.java:632)
	at org.testng.SuiteRunner.runTest(SuiteRunner.java:366)
	at org.testng.SuiteRunner.runSequentially(SuiteRunner.java:361)
	at org.testng.SuiteRunner.privateRun(SuiteRunner.java:319)
	at org.testng.SuiteRunner.run(SuiteRunner.java:268)
	at org.testng.SuiteRunnerWorker.runSuite(SuiteRunnerWorker.java:52)
	at org.testng.SuiteRunnerWorker.run(SuiteRunnerWorker.java:86)
	at org.testng.TestNG.runSuitesSequentially(TestNG.java:1244)
	at org.testng.TestNG.runSuitesLocally(TestNG.java:1169)
	at org.testng.TestNG.run(TestNG.java:1064)
	at org.testng.remote.RemoteTestNG.run(RemoteTestNG.java:113)
	at org.testng.remote.RemoteTestNG.initAndRun(RemoteTestNG.java:206)
	at org.testng.remote.RemoteTestNG.main(RemoteTestNG.java:177)
]]>
    </failure>
  </testcase> <!-- withdraw -->
  <testcase name="withdraw" time="0.804" classname="main.testcase.Wallet.Withdraw"/>
  <testcase name="withdraw" time="0.607" classname="main.testcase.Wallet.Withdraw"/>
  <testcase name="withdraw" time="0.727" classname="main.testcase.Wallet.Withdraw"/>
  <testcase name="withdraw" time="0.683" classname="main.testcase.Wallet.Withdraw"/>
  <testcase name="withdraw" time="0.668" classname="main.testcase.Wallet.Withdraw"/>
</testsuite> <!-- main.testcase.Wallet.Withdraw -->
